Workbook

Sheet 📋 How To Use
A1: Portfolio & Mutual Fund Management Template — User Guide
A3: SHEET
A4: 📥 Stock Data Input | B4: Enter equity holdings. Fill: Scrip Name, Qty, Buy Price, Buy Date, Current Price, Sector, Exchange. All other columns auto-calculate.
A5: 📥 MF Data Input | B5: Enter mutual fund holdings. Fill: Fund Name, AMC, Category, Units, Buy NAV, Buy Date, Current NAV, Benchmark Return %. Returns auto-calculate.
A6: 📊 Stock Analysis | B6: Auto-generated P&L, XIRR estimate, weight, and signals for every stock. Pulls from Stock Data Input — do not edit.
A7: 📊 MF Analysis | B7: Auto-generated returns, alpha vs benchmark, and signals for every fund. Pulls from MF Data Input — do not edit.
A8: 🎯 Dashboard | B8: Executive summary: total value, combined P&L, top/bottom 5 performers, asset allocation split. All auto-calculated.
A9: 📈 Sector Allocation | B9: Sector-wise equity breakdown with value, return, and concentration weight. Auto-calculated.
A10: ⚠️ Risk & Signals | B10: Summary counts + detailed flags: loss positions, underperformers, low-qty holdings, MFs below benchmark. Auto-calculated.
A12: COLOR LEGEND
A13: 🔵 Blue cell background | B13: → Input cell: YOU must fill this in
A14: ⚫ Black text | B14: → Formula cell: auto-calculated, do not edit
A15: 🟢 Green signal | B15: → Strong performer / Hold / Outperforming
A16: 🟡 Amber signal | B16: → Watch / Review / Below benchmark
A17: 🔴 Red signal | B17: → Underperformer / Loss / Consider exit
A19: QUICK START
A20: Step 1 | B20: Go to 📥 Stock Data Input → enter your stock holdings row by row
A21: Step 2 | B21: Go to 📥 MF Data Input → enter your mutual fund holdings
A22: Step 3 | B22: All analysis sheets update automatically — no manual work needed
A23: Step 4 | B23: Check 🎯 Dashboard for full portfolio summary
A24: Step 5 | B24: Check ⚠️ Risk & Signals for prioritised action list
A26: NOTES
A27: Buy Price | B27: Enter the average cost per share. For multiple purchases, use weighted average buy price.
A28: Current Price | B28: Update this periodically to refresh all calculations across all sheets.
A29: 5Y CAGR | B29: Enter manually from Screener.in, Tickertape, or Moneycontrol. Used for benchmark comparison.
A30: Nifty 5Y CAGR | B30: Enter 14 as a default (Nifty 50 delivered ~14% CAGR over last 5 years). Adjust if needed.
A31: XIRR | B31: Approximate annualised return from buy date to today. For precise XIRR, use broker statement.
A32: Benchmark (MF) | B32: Enter 1Y benchmark return % from the fund factsheet or AMFI website.

Sheet 🎯 Dashboard
A1: Investment Portfolio — Executive Dashboard
A3: 📊 PORTFOLIO SUMMARY
A4: Total Stock Value (₹) | C4: Total MF Value (₹) | E4: Combined Portfolio (₹) | G4: Total Unrealised P&L (₹)
A5: ='📥 Stock Data Input'!K54 | C5: ='📥 MF Data Input'!L44 | E5: ='📥 Stock Data Input'!K54+'📥 MF Data Input'!L44 | G5: ='📥 Stock Data Input'!L54+'📥 MF Data Input'!M44
A7: Stock Invested (₹) | C7: MF Invested (₹) | E7: Total Invested (₹) | G7: Overall Return %
A8: ='📥 Stock Data Input'!J54 | C8: ='📥 MF Data Input'!K44 | E8: ='📥 Stock Data Input'!J54+'📥 MF Data Input'!K44 | G8: =IFERROR(('📥 Stock Data Input'!K54+'📥 MF Data Input'!L44-'📥 Stock Data Input'!J54-'📥 MF Data Input'!K44)/('📥 Stock Data Input'!J54+'📥 MF Data Input'!K44),0)
A10: 🥧 ASSET ALLOCATION
A11: Asset Class | B11: Invested (₹) | C11: Current Value (₹) | D11: P&L (₹) | E11: Return % | F11: % of Total Portfolio
A12: Equities (Stocks) | B12: ='📥 Stock Data Input'!J54 | C12: ='📥 Stock Data Input'!K54 | D12: =IFERROR(C12-B12,0) | E12: =IFERROR((C12-B12)/B12,0) | F12: =IFERROR(C12/(C12+C13),0)
A13: Mutual Funds | B13: ='📥 MF Data Input'!K44 | C13: ='📥 MF Data Input'!L44 | D13: =IFERROR(C13-B13,0) | E13: =IFERROR((C13-B13)/B13,0) | F13: =IFERROR(C13/(C12+C13),0)
A14: TOTAL | B14: =SUM(B12:B13) | C14: =SUM(C12:C13) | D14: =SUM(D12:D13) | E14: =IFERROR((C14-B14)/B14,0) | F14: =1
A16: 🏆 TOP 5 STOCK PERFORMERS (by Return %)
A17: Rank | B17: Scrip Name | C17: Sector | D17: Qty | E17: Invested (₹) | F17: Current (₹) | G17: P&L (₹) | H17: Return %
A18: #1 | B18: {=IFERROR(INDEX('📥 Stock Data Input'!$A$4:$A$53,MATCH(LARGE('📥 Stock Data Input'!$M$4:$M$53,1),'📥 Stock Data Input'!$M$4:$M$53,0)),"")} | C18: {=IFERROR(INDEX('📥 Stock Data Input'!$C$4:$C$53,MATCH(LARGE('📥 Stock Data Input'!$M$4:$M$53,1),'📥 Stock Data Input'!$M$4:$M$53,0)),"")} | D18: {=IFERROR(INDEX('📥 Stock Data Input'!$D$4:$D$53,MATCH(LARGE('📥 Stock Data Input'!$M$4:$M$53,1),'📥 Stock Data Input'!$M$4:$M$53,0)),"")} | E18: {=IFERROR(INDEX('📥 Stock Data Input'!$J$4:$J$53,MATCH(LARGE('📥 Stock Data Input'!$M$4:$M$53,1),'📥 Stock Data Input'!$M$4:$M$53,0)),"")} | F18: {=IFERROR(INDEX('📥 Stock Data Input'!$K$4:$K$53,MATCH(LARGE('📥 Stock Data Input'!$M$4:$M$53,1),'📥 Stock Data Input'!$M$4:$M$53,0)),"")} | G18: {=IFERROR(INDEX('📥 Stock Data Input'!$L$4:$L$53,MATCH(LARGE('📥 Stock Data Input'!$M$4:$M$53,1),'📥 Stock Data Input'!$M$4:$M$53,0)),"")} | H18: =IFERROR(LARGE('📥 Stock Data Input'!$M$4:$M$53,1),"")
A19: #2 | B19: {=IFERROR(INDEX('📥 Stock Data Input'!$A$4:$A$53,MATCH(LARGE('📥 Stock Data Input'!$M$4:$M$53,2),'📥 Stock Data Input'!$M$4:$M$53,0)),"")} | C19: {=IFERROR(INDEX('📥 Stock Data Input'!$C$4:$C$53,MATCH(LARGE('📥 Stock Data Input'!$M$4:$M$53,2),'📥 Stock Data Input'!$M$4:$M$53,0)),"")} | D19: {=IFERROR(INDEX('📥 Stock Data Input'!$D$4:$D$53,MATCH(LARGE('📥 Stock Data Input'!$M$4:$M$53,2),'📥 Stock Data Input'!$M$4:$M$53,0)),"")} | E19: {=IFERROR(INDEX('📥 Stock Data Input'!$J$4:$J$53,MATCH(LARGE('📥 Stock Data Input'!$M$4:$M$53,2),'📥 Stock Data Input'!$M$4:$M$53,0)),"")} | F19: {=IFERROR(INDEX('📥 Stock Data Input'!$K$4:$K$53,MATCH(LARGE('📥 Stock Data Input'!$M$4:$M$53,2),'📥 Stock Data Input'!$M$4:$M$53,0)),"")} | G19: {=IFERROR(INDEX('📥 Stock Data Input'!$L$4:$L$53,MATCH(LARGE('📥 Stock Data Input'!$M$4:$M$53,2),'📥 Stock Data Input'!$M$4:$M$53,0)),"")} | H19: =IFERROR(LARGE('📥 Stock Data Input'!$M$4:$M$53,2),"")
A20: #3 | B20: {=IFERROR(INDEX('📥 Stock Data Input'!$A$4:$A$53,MATCH(LARGE('📥 Stock Data Input'!$M$4:$M$53,3),'📥 Stock Data Input'!$M$4:$M$53,0)),"")} | C20: {=IFERROR(INDEX('📥 Stock Data Input'!$C$4:$C$53,MATCH(LARGE('📥 Stock Data Input'!$M$4:$M$53,3),'📥 Stock Data Input'!$M$4:$M$53,0)),"")} | D20: {=IFERROR(INDEX('📥 Stock Data Input'!$D$4:$D$53,MATCH(LARGE('📥 Stock Data Input'!$M$4:$M$53,3),'📥 Stock Data Input'!$M$4:$M$53,0)),"")} | E20: {=IFERROR(INDEX('📥 Stock Data Input'!$J$4:$J$53,MATCH(LARGE('📥 Stock Data Input'!$M$4:$M$53,3),'📥 Stock Data Input'!$M$4:$M$53,0)),"")} | F20: {=IFERROR(INDEX('📥 Stock Data Input'!$K$4:$K$53,MATCH(LARGE('📥 Stock Data Input'!$M$4:$M$53,3),'📥 Stock Data Input'!$M$4:$M$53,0)),"")} | G20: {=IFERROR(INDEX('📥 Stock Data Input'!$L$4:$L$53,MATCH(LARGE('📥 Stock Data Input'!$M$4:$M$53,3),'📥 Stock Data Input'!$M$4:$M$53,0)),"")} | H20: =IFERROR(LARGE('📥 Stock Data Input'!$M$4:$M$53,3),"")
A21: #4 | B21: {=IFERROR(INDEX('📥 Stock Data Input'!$A$4:$A$53,MATCH(LARGE('📥 Stock Data Input'!$M$4:$M$53,4),'📥 Stock Data Input'!$M$4:$M$53,0)),"")} | C21: {=IFERROR(INDEX('📥 Stock Data Input'!$C$4:$C$53,MATCH(LARGE('📥 Stock Data Input'!$M$4:$M$53,4),'📥 Stock Data Input'!$M$4:$M$53,0)),"")} | D21: {=IFERROR(INDEX('📥 Stock Data Input'!$D$4:$D$53,MATCH(LARGE('📥 Stock Data Input'!$M$4:$M$53,4),'📥 Stock Data Input'!$M$4:$M$53,0)),"")} | E21: {=IFERROR(INDEX('📥 Stock Data Input'!$J$4:$J$53,MATCH(LARGE('📥 Stock Data Input'!$M$4:$M$53,4),'📥 Stock Data Input'!$M$4:$M$53,0)),"")} | F21: {=IFERROR(INDEX('📥 Stock Data Input'!$K$4:$K$53,MATCH(LARGE('📥 Stock Data Input'!$M$4:$M$53,4),'📥 Stock Data Input'!$M$4:$M$53,0)),"")} | G21: {=IFERROR(INDEX('📥 Stock Data Input'!$L$4:$L$53,MATCH(LARGE('📥 Stock Data Input'!$M$4:$M$53,4),'📥 Stock Data Input'!$M$4:$M$53,0)),"")} | H21: =IFERROR(LARGE('📥 Stock Data Input'!$M$4:$M$53,4),"")
A22: #5 | B22: {=IFERROR(INDEX('📥 Stock Data Input'!$A$4:$A$53,MATCH(LARGE('📥 Stock Data Input'!$M$4:$M$53,5),'📥 Stock Data Input'!$M$4:$M$53,0)),"")} | C22: {=IFERROR(INDEX('📥 Stock Data Input'!$C$4:$C$53,MATCH(LARGE('📥 Stock Data Input'!$M$4:$M$53,5),'📥 Stock Data Input'!$M$4:$M$53,0)),"")} | D22: {=IFERROR(INDEX('📥 Stock Data Input'!$D$4:$D$53,MATCH(LARGE('📥 Stock Data Input'!$M$4:$M$53,5),'📥 Stock Data Input'!$M$4:$M$53,0)),"")} | E22: {=IFERROR(INDEX('📥 Stock Data Input'!$J$4:$J$53,MATCH(LARGE('📥 Stock Data Input'!$M$4:$M$53,5),'📥 Stock Data Input'!$M$4:$M$53,0)),"")} | F22: {=IFERROR(INDEX('📥 Stock Data Input'!$K$4:$K$53,MATCH(LARGE('📥 Stock Data Input'!$M$4:$M$53,5),'📥 Stock Data Input'!$M$4:$M$53,0)),"")} | G22: {=IFERROR(INDEX('📥 Stock Data Input'!$L$4:$L$53,MATCH(LARGE('📥 Stock Data Input'!$M$4:$M$53,5),'📥 Stock Data Input'!$M$4:$M$53,0)),"")} | H22: =IFERROR(LARGE('📥 Stock Data Input'!$M$4:$M$53,5),"")
A24: 📉 BOTTOM 5 STOCK PERFORMERS (by Return %)
A25: Rank | B25: Scrip Name | C25: Sector | D25: Qty | E25: Invested (₹) | F25: Current (₹) | G25: P&L (₹) | H25: Return %
A26: #1 | B26: {=IFERROR(INDEX('📥 Stock Data Input'!$A$4:$A$53,MATCH(SMALL('📥 Stock Data Input'!$M$4:$M$53,1),'📥 Stock Data Input'!$M$4:$M$53,0)),"")} | C26: {=IFERROR(INDEX('📥 Stock Data Input'!$C$4:$C$53,MATCH(SMALL('📥 Stock Data Input'!$M$4:$M$53,1),'📥 Stock Data Input'!$M$4:$M$53,0)),"")} | D26: {=IFERROR(INDEX('📥 Stock Data Input'!$D$4:$D$53,MATCH(SMALL('📥 Stock Data Input'!$M$4:$M$53,1),'📥 Stock Data Input'!$M$4:$M$53,0)),"")} | E26: {=IFERROR(INDEX('📥 Stock Data Input'!$J$4:$J$53,MATCH(SMALL('📥 Stock Data Input'!$M$4:$M$53,1),'📥 Stock Data Input'!$M$4:$M$53,0)),"")} | F26: {=IFERROR(INDEX('📥 Stock Data Input'!$K$4:$K$53,MATCH(SMALL('📥 Stock Data Input'!$M$4:$M$53,1),'📥 Stock Data Input'!$M$4:$M$53,0)),"")} | G26: {=IFERROR(INDEX('📥 Stock Data Input'!$L$4:$L$53,MATCH(SMALL('📥 Stock Data Input'!$M$4:$M$53,1),'📥 Stock Data Input'!$M$4:$M$53,0)),"")} | H26: =IFERROR(SMALL('📥 Stock Data Input'!$M$4:$M$53,1),"")
A27: #2 | B27: {=IFERROR(INDEX('📥 Stock Data Input'!$A$4:$A$53,MATCH(SMALL('📥 Stock Data Input'!$M$4:$M$53,2),'📥 Stock Data Input'!$M$4:$M$53,0)),"")} | C27: {=IFERROR(INDEX('📥 Stock Data Input'!$C$4:$C$53,MATCH(SMALL('📥 Stock Data Input'!$M$4:$M$53,2),'📥 Stock Data Input'!$M$4:$M$53,0)),"")} | D27: {=IFERROR(INDEX('📥 Stock Data Input'!$D$4:$D$53,MATCH(SMALL('📥 Stock Data Input'!$M$4:$M$53,2),'📥 Stock Data Input'!$M$4:$M$53,0)),"")} | E27: {=IFERROR(INDEX('📥 Stock Data Input'!$J$4:$J$53,MATCH(SMALL('📥 Stock Data Input'!$M$4:$M$53,2),'📥 Stock Data Input'!$M$4:$M$53,0)),"")} | F27: {=IFERROR(INDEX('📥 Stock Data Input'!$K$4:$K$53,MATCH(SMALL('📥 Stock Data Input'!$M$4:$M$53,2),'📥 Stock Data Input'!$M$4:$M$53,0)),"")} | G27: {=IFERROR(INDEX('📥 Stock Data Input'!$L$4:$L$53,MATCH(SMALL('📥 Stock Data Input'!$M$4:$M$53,2),'📥 Stock Data Input'!$M$4:$M$53,0)),"")} | H27: =IFERROR(SMALL('📥 Stock Data Input'!$M$4:$M$53,2),"")
A28: #3 | B28: {=IFERROR(INDEX('📥 Stock Data Input'!$A$4:$A$53,MATCH(SMALL('📥 Stock Data Input'!$M$4:$M$53,3),'📥 Stock Data Input'!$M$4:$M$53,0)),"")} | C28: {=IFERROR(INDEX('📥 Stock Data Input'!$C$4:$C$53,MATCH(SMALL('📥 Stock Data Input'!$M$4:$M$53,3),'📥 Stock Data Input'!$M$4:$M$53,0)),"")} | D28: {=IFERROR(INDEX('📥 Stock Data Input'!$D$4:$D$53,MATCH(SMALL('📥 Stock Data Input'!$M$4:$M$53,3),'📥 Stock Data Input'!$M$4:$M$53,0)),"")} | E28: {=IFERROR(INDEX('📥 Stock Data Input'!$J$4:$J$53,MATCH(SMALL('📥 Stock Data Input'!$M$4:$M$53,3),'📥 Stock Data Input'!$M$4:$M$53,0)),"")} | F28: {=IFERROR(INDEX('📥 Stock Data Input'!$K$4:$K$53,MATCH(SMALL('📥 Stock Data Input'!$M$4:$M$53,3),'📥 Stock Data Input'!$M$4:$M$53,0)),"")} | G28: {=IFERROR(INDEX('📥 Stock Data Input'!$L$4:$L$53,MATCH(SMALL('📥 Stock Data Input'!$M$4:$M$53,3),'📥 Stock Data Input'!$M$4:$M$53,0)),"")} | H28: =IFERROR(SMALL('📥 Stock Data Input'!$M$4:$M$53,3),"")
A29: #4 | B29: {=IFERROR(INDEX('📥 Stock Data Input'!$A$4:$A$53,MATCH(SMALL('📥 Stock Data Input'!$M$4:$M$53,4),'📥 Stock Data Input'!$M$4:$M$53,0)),"")} | C29: {=IFERROR(INDEX('📥 Stock Data Input'!$C$4:$C$53,MATCH(SMALL('📥 Stock Data Input'!$M$4:$M$53,4),'📥 Stock Data Input'!$M$4:$M$53,0)),"")} | D29: {=IFERROR(INDEX('📥 Stock Data Input'!$D$4:$D$53,MATCH(SMALL('📥 Stock Data Input'!$M$4:$M$53,4),'📥 Stock Data Input'!$M$4:$M$53,0)),"")} | E29: {=IFERROR(INDEX('📥 Stock Data Input'!$J$4:$J$53,MATCH(SMALL('📥 Stock Data Input'!$M$4:$M$53,4),'📥 Stock Data Input'!$M$4:$M$53,0)),"")} | F29: {=IFERROR(INDEX('📥 Stock Data Input'!$K$4:$K$53,MATCH(SMALL('📥 Stock Data Input'!$M$4:$M$53,4),'📥 Stock Data Input'!$M$4:$M$53,0)),"")} | G29: {=IFERROR(INDEX('📥 Stock Data Input'!$L$4:$L$53,MATCH(SMALL('📥 Stock Data Input'!$M$4:$M$53,4),'📥 Stock Data Input'!$M$4:$M$53,0)),"")} | H29: =IFERROR(SMALL('📥 Stock Data Input'!$M$4:$M$53,4),"")
A30: #5 | B30: {=IFERROR(INDEX('📥 Stock Data Input'!$A$4:$A$53,MATCH(SMALL('📥 Stock Data Input'!$M$4:$M$53,5),'📥 Stock Data Input'!$M$4:$M$53,0)),"")} | C30: {=IFERROR(INDEX('📥 Stock Data Input'!$C$4:$C$53,MATCH(SMALL('📥 Stock Data Input'!$M$4:$M$53,5),'📥 Stock Data Input'!$M$4:$M$53,0)),"")} | D30: {=IFERROR(INDEX('📥 Stock Data Input'!$D$4:$D$53,MATCH(SMALL('📥 Stock Data Input'!$M$4:$M$53,5),'📥 Stock Data Input'!$M$4:$M$53,0)),"")} | E30: {=IFERROR(INDEX('📥 Stock Data Input'!$J$4:$J$53,MATCH(SMALL('📥 Stock Data Input'!$M$4:$M$53,5),'📥 Stock Data Input'!$M$4:$M$53,0)),"")} | F30: {=IFERROR(INDEX('📥 Stock Data Input'!$K$4:$K$53,MATCH(SMALL('📥 Stock Data Input'!$M$4:$M$53,5),'📥 Stock Data Input'!$M$4:$M$53,0)),"")} | G30: {=IFERROR(INDEX('📥 Stock Data Input'!$L$4:$L$53,MATCH(SMALL('📥 Stock Data Input'!$M$4:$M$53,5),'📥 Stock Data Input'!$M$4:$M$53,0)),"")} | H30: =IFERROR(SMALL('📥 Stock Data Input'!$M$4:$M$53,5),"")

Sheet 📥 Stock Data Input
A1: Stock Holdings — Data Entry
A2: 🔵 Fill BLUE columns only (A–I). Columns J–O are auto-calculated formulas. Add more rows by copying row 53 down. Enter 5Y CAGR & Nifty CAGR as numbers (e.g. 14 for 14%).
A3: Scrip Name | B3: Exchange (NSE/BSE) | C3: Sector | D3: Qty (Shares) | E3: Buy / AVG Price (₹) | F3: Buy Date (DD-MM-YYYY) | G3: Current Price (₹) | H3: 5Y CAGR (%) | I3: Nifty 5Y CAGR (%) | J3: Invested Value (₹) | K3: Current Value (₹) | L3: P&L (₹) | M3: Return % | N3: Approx XIRR % | O3: Portfolio Wt % | P3: Dividends Received (₹) | Q3: Tax Flag | R3: Total Return (w/ Div)
A4: ADANI POWER LTD | B4: NSE | C4: Utilities | D4: 90 | E4: 101.3 | G4: 227.05 | J4: =D4*E4 | K4: =D4*G4 | L4: =K4-J4 | M4: =IF(J4=0,0,L4/J4) | P4: 0 | Q4: =IF(ISBLANK(F4),"",IF(TODAY()-F4>365,"LTCG","STCG")) | R4: =L4+IF(ISNUMBER(P4),P4,0)
A5: COAL INDIA LTD | B5: NSE | C5: Energy | D5: 8 | E5: 413.25 | G5: 444.85 | J5: =D5*E5 | K5: =D5*G5 | L5: =K5-J5 | M5: =IF(J5=0,0,L5/J5) | P5: 0 | Q5: =IF(ISBLANK(F5),"",IF(TODAY()-F5>365,"LTCG","STCG")) | R5: =L5+IF(ISNUMBER(P5),P5,0)
A6: ETERNAL LIMITED | B6: NSE | C6: Consumer Discretionary | D6: 26 | E6: 246.68 | G6: 259.4 | J6: =D6*E6 | K6: =D6*G6 | L6: =K6-J6 | M6: =IF(J6=0,0,L6/J6) | P6: 0 | Q6: =IF(ISBLANK(F6),"",IF(TODAY()-F6>365,"LTCG","STCG")) | R6: =L6+IF(ISNUMBER(P6),P6,0)
A7: INDIAN OIL CORP LTD | B7: NSE | C7: Energy | D7: 14 | E7: 115.73 | G7: 139.18 | J7: =D7*E7 | K7: =D7*G7 | L7: =K7-J7 | M7: =IF(J7=0,0,L7/J7) | P7: 0 | Q7: =IF(ISBLANK(F7),"",IF(TODAY()-F7>365,"LTCG","STCG")) | R7: =L7+IF(ISNUMBER(P7),P7,0)
A8: MAHINDRA & MAHINDRA LTD | B8: NSE | C8: Consumer Discretionary | D8: 5 | E8: 2689.81 | G8: 3093 | J8: =D8*E8 | K8: =D8*G8 | L8: =K8-J8 | M8: =IF(J8=0,0,L8/J8) | P8: 0 | Q8: =IF(ISBLANK(F8),"",IF(TODAY()-F8>365,"LTCG","STCG")) | R8: =L8+IF(ISNUMBER(P8),P8,0)
A9: MOTILALAMC - MONIFTY500 | B9: NSE | C9: ETF | D9: 65 | E9: 23.05 | G9: 23.6 | J9: =D9*E9 | K9: =D9*G9 | L9: =K9-J9 | M9: =IF(J9=0,0,L9/J9) | P9: 0 | Q9: =IF(ISBLANK(F9),"",IF(TODAY()-F9>365,"LTCG","STCG")) | R9: =L9+IF(ISNUMBER(P9),P9,0)
A10: NIP IND ETF GOLD BEES | B10: NSE | C10: ETF | D10: 14 | E10: 114.82 | G10: 116.43 | J10: =D10*E10 | K10: =D10*G10 | L10: =K10-J10 | M10: =IF(J10=0,0,L10/J10) | P10: 0 | Q10: =IF(ISBLANK(F10),"",IF(TODAY()-F10>365,"LTCG","STCG")) | R10: =L10+IF(ISNUMBER(P10),P10,0)
A11: TATA MOTORS LIMITED | B11: NSE | C11: Consumer Discretionary | D11: 5 | E11: 194.81 | G11: 423.1 | J11: =D11*E11 | K11: =D11*G11 | L11: =K11-J11 | M11: =IF(J11=0,0,L11/J11) | P11: 0 | Q11: =IF(ISBLANK(F11),"",IF(TODAY()-F11>365,"LTCG","STCG")) | R11: =L11+IF(ISNUMBER(P11),P11,0)
A12: TATA MOTORS PASS VEH LTD | B12: NSE | C12: Consumer Discretionary | D12: 5 | E12: 430.58 | G12: 345.05 | J12: =D12*E12 | K12: =D12*G12 | L12: =K12-J12 | M12: =IF(J12=0,0,L12/J12) | P12: 0 | Q12: =IF(ISBLANK(F12),"",IF(TODAY()-F12>365,"LTCG","STCG")) | R12: =L12+IF(ISNUMBER(P12),P12,0)
A13: TATA STEEL LIMITED | B13: NSE | C13: Materials | D13: 4 | E13: 135.85 | G13: 189.57 | J13: =D13*E13 | K13: =D13*G13 | L13: =K13-J13 | M13: =IF(J13=0,0,L13/J13) | P13: 0 | Q13: =IF(ISBLANK(F13),"",IF(TODAY()-F13>365,"LTCG","STCG")) | R13: =L13+IF(ISNUMBER(P13),P13,0)
A14: TATAAML-TATAGOLD | B14: NSE | C14: ETF | D14: 104 | E14: 14.62 | G14: 13.68 | J14: =D14*E14 | K14: =D14*G14 | L14: =K14-J14 | M14: =IF(J14=0,0,L14/J14) | P14: 0 | Q14: =IF(ISBLANK(F14),"",IF(TODAY()-F14>365,"LTCG","STCG")) | R14: =L14+IF(ISNUMBER(P14),P14,0)
A15: VEDANTA LIMITED | B15: NSE | C15: Materials | D15: 18 | E15: 467.7 | G15: 284.55 | J15: =D15*E15 | K15: =D15*G15 | L15: =K15-J15 | M15: =IF(J15=0,0,L15/J15) | P15: 0 | Q15: =IF(ISBLANK(F15),"",IF(TODAY()-F15>365,"LTCG","STCG")) | R15: =L15+IF(ISNUMBER(P15),P15,0)
A16: VODAFONE IDEA LIMITED | B16: NSE | C16: Communication | D16: 15 | E16: 9.22 | G16: 14.43 | J16: =D16*E16 | K16: =D16*G16 | L16: =K16-J16 | M16: =IF(J16=0,0,L16/J16) | P16: 0 | Q16: =IF(ISBLANK(F16),"",IF(TODAY()-F16>365,"LTCG","STCG")) | R16: =L16+IF(ISNUMBER(P16),P16,0)

Sheet 📥 MF Data Input
A1: Mutual Fund Holdings — Data Entry
A2: 🔵 Fill BLUE columns only (A–J). Columns K–P are auto-calculated. Enter benchmark 1Y return as a number (e.g. 15 for 15%). Get current NAV from AMC site / MFCentral / CAMS.
A3: Fund Name | B3: AMC | C3: Category | D3: Sub-Category (Large/Mid/Small/Hybrid/Debt) | E3: Units Held | F3: Buy NAV (₹) | G3: Buy Date (DD-MM-YYYY) | H3: Current NAV (₹) | I3: Benchmark 1Y Return % | J3: Expense Ratio % | K3: Invested Value (₹) | L3: Current Value (₹) | M3: P&L (₹) | N3: Absolute Return % | O3: CAGR (Annualised) % | P3: Portfolio Weight % | Q3: Tax Flag

Sheet 📊 Stock Analysis
A1: Stock Portfolio — Automated Analysis
A2: ⚙️ All columns auto-calculated from 📥 Stock Data Input. Do NOT edit this sheet. Refresh by updating prices in the input sheet.
A3: Scrip Name | B3: Sector | C3: Qty | D3: Invested (₹) | E3: Current Value (₹) | F3: P&L (₹) | G3: Return % | H3: Ann. XIRR % | I3: Portfolio Wt% | J3: vs 5Y CAGR | K3: vs Nifty 5Y | L3: Signal | M3: Recommended Action
A4: ='📥 Stock Data Input'!A4 | B4: ='📥 Stock Data Input'!C4 | C4: ='📥 Stock Data Input'!D4 | D4: ='📥 Stock Data Input'!J4 | E4: ='📥 Stock Data Input'!K4 | F4: ='📥 Stock Data Input'!L4 | G4: ='📥 Stock Data Input'!M4 | H4: ='📥 Stock Data Input'!N4 | I4: ='📥 Stock Data Input'!O4 | J4: =IFERROR(IF('📥 Stock Data Input'!H4="","N/A",IF('📥 Stock Data Input'!N4>'📥 Stock Data Input'!H4/100,"✅ Outperform","❌ Underperform")),"N/A") | K4: =IFERROR(IF('📥 Stock Data Input'!I4="","N/A",IF('📥 Stock Data Input'!N4>'📥 Stock Data Input'!I4/100,"✅ Beat Nifty","❌ Lag Nifty")),"N/A") | L4: =IFERROR(IF('📥 Stock Data Input'!A4="","",IF('📥 Stock Data Input'!K4<5000,"⚠️ Tiny Position",IF('📥 Stock Data Input'!N4<0,"🔴 In Loss",IF(AND('📥 Stock Data Input'!I4<>"",'📥 Stock Data Input'!N4<'📥 Stock Data Input'!I4/100),"🟡 Underperform",IF('📥 Stock Data Input'!N4>0.2,"🟢 Strong","🔵 Hold"))))),"") | M4: =IFERROR(IF('📥 Stock Data Input'!A4="","",IF('📥 Stock Data Input'!K4<5000,"Add qty meaningfully or exit — position too small to matter",IF('📥 Stock Data Input'!N4<-0.2,"Consider exit — loss >20%; re-evaluate thesis",IF(AND('📥 Stock Data Input'!I4<>"",'📥 Stock Data Input'!N4<'📥 Stock Data Input'!I4/100),"Lagging benchmark — review thesis; rotate if 2+ years",IF('📥 Stock Data Input'!N4>0.2,"Strong compounder — hold; consider adding on dips","Hold — monitor quarterly; no immediate action"))))),"")
A5: ='📥 Stock Data Input'!A5 | B5: ='📥 Stock Data Input'!C5 | C5: ='📥 Stock Data Input'!D5 | D5: ='📥 Stock Data Input'!J5 | E5: ='📥 Stock Data Input'!K5 | F5: ='📥 Stock Data Input'!L5 | G5: ='📥 Stock Data Input'!M5 | H5: ='📥 Stock Data Input'!N5 | I5: ='📥 Stock Data Input'!O5 | J5: =IFERROR(IF('📥 Stock Data Input'!H5="","N/A",IF('📥 Stock Data Input'!N5>'📥 Stock Data Input'!H5/100,"✅ Outperform","❌ Underperform")),"N/A") | K5: =IFERROR(IF('📥 Stock Data Input'!I5="","N/A",IF('📥 Stock Data Input'!N5>'📥 Stock Data Input'!I5/100,"✅ Beat Nifty","❌ Lag Nifty")),"N/A") | L5: =IFERROR(IF('📥 Stock Data Input'!A5="","",IF('📥 Stock Data Input'!K5<5000,"⚠️ Tiny Position",IF('📥 Stock Data Input'!N5<0,"🔴 In Loss",IF(AND('📥 Stock Data Input'!I5<>"",'📥 Stock Data Input'!N5<'📥 Stock Data Input'!I5/100),"🟡 Underperform",IF('📥 Stock Data Input'!N5>0.2,"🟢 Strong","🔵 Hold"))))),"") | M5: =IFERROR(IF('📥 Stock Data Input'!A5="","",IF('📥 Stock Data Input'!K5<5000,"Add qty meaningfully or exit — position too small to matter",IF('📥 Stock Data Input'!N5<-0.2,"Consider exit — loss >20%; re-evaluate thesis",IF(AND('📥 Stock Data Input'!I5<>"",'📥 Stock Data Input'!N5<'📥 Stock Data Input'!I5/100),"Lagging benchmark — review thesis; rotate if 2+ years",IF('📥 Stock Data Input'!N5>0.2,"Strong compounder — hold; consider adding on dips","Hold — monitor quarterly; no immediate action"))))),"")
A6: ='📥 Stock Data Input'!A6 | B6: ='📥 Stock Data Input'!C6 | C6: ='📥 Stock Data Input'!D6 | D6: ='📥 Stock Data Input'!J6 | E6: ='📥 Stock Data Input'!K6 | F6: ='📥 Stock Data Input'!L6 | G6: ='📥 Stock Data Input'!M6 | H6: ='📥 Stock Data Input'!N6 | I6: ='📥 Stock Data Input'!O6 | J6: =IFERROR(IF('📥 Stock Data Input'!H6="","N/A",IF('📥 Stock Data Input'!N6>'📥 Stock Data Input'!H6/100,"✅ Outperform","❌ Underperform")),"N/A") | K6: =IFERROR(IF('📥 Stock Data Input'!I6="","N/A",IF('📥 Stock Data Input'!N6>'📥 Stock Data Input'!I6/100,"✅ Beat Nifty","❌ Lag Nifty")),"N/A") | L6: =IFERROR(IF('📥 Stock Data Input'!A6="","",IF('📥 Stock Data Input'!K6<5000,"⚠️ Tiny Position",IF('📥 Stock Data Input'!N6<0,"🔴 In Loss",IF(AND('📥 Stock Data Input'!I6<>"",'📥 Stock Data Input'!N6<'📥 Stock Data Input'!I6/100),"🟡 Underperform",IF('📥 Stock Data Input'!N6>0.2,"🟢 Strong","🔵 Hold"))))),"") | M6: =IFERROR(IF('📥 Stock Data Input'!A6="","",IF('📥 Stock Data Input'!K6<5000,"Add qty meaningfully or exit — position too small to matter",IF('📥 Stock Data Input'!N6<-0.2,"Consider exit — loss >20%; re-evaluate thesis",IF(AND('📥 Stock Data Input'!I6<>"",'📥 Stock Data Input'!N6<'📥 Stock Data Input'!I6/100),"Lagging benchmark — review thesis; rotate if 2+ years",IF('📥 Stock Data Input'!N6>0.2,"Strong compounder — hold; consider adding on dips","Hold — monitor quarterly; no immediate action"))))),"")
A7: ='📥 Stock Data Input'!A7 | B7: ='📥 Stock Data Input'!C7 | C7: ='📥 Stock Data Input'!D7 | D7: ='📥 Stock Data Input'!J7 | E7: ='📥 Stock Data Input'!K7 | F7: ='📥 Stock Data Input'!L7 | G7: ='📥 Stock Data Input'!M7 | H7: ='📥 Stock Data Input'!N7 | I7: ='📥 Stock Data Input'!O7 | J7: =IFERROR(IF('📥 Stock Data Input'!H7="","N/A",IF('📥 Stock Data Input'!N7>'📥 Stock Data Input'!H7/100,"✅ Outperform","❌ Underperform")),"N/A") | K7: =IFERROR(IF('📥 Stock Data Input'!I7="","N/A",IF('📥 Stock Data Input'!N7>'📥 Stock Data Input'!I7/100,"✅ Beat Nifty","❌ Lag Nifty")),"N/A") | L7: =IFERROR(IF('📥 Stock Data Input'!A7="","",IF('📥 Stock Data Input'!K7<5000,"⚠️ Tiny Position",IF('📥 Stock Data Input'!N7<0,"🔴 In Loss",IF(AND('📥 Stock Data Input'!I7<>"",'📥 Stock Data Input'!N7<'📥 Stock Data Input'!I7/100),"🟡 Underperform",IF('📥 Stock Data Input'!N7>0.2,"🟢 Strong","🔵 Hold"))))),"") | M7: =IFERROR(IF('📥 Stock Data Input'!A7="","",IF('📥 Stock Data Input'!K7<5000,"Add qty meaningfully or exit — position too small to matter",IF('📥 Stock Data Input'!N7<-0.2,"Consider exit — loss >20%; re-evaluate thesis",IF(AND('📥 Stock Data Input'!I7<>"",'📥 Stock Data Input'!N7<'📥 Stock Data Input'!I7/100),"Lagging benchmark — review thesis; rotate if 2+ years",IF('📥 Stock Data Input'!N7>0.2,"Strong compounder — hold; consider adding on dips","Hold — monitor quarterly; no immediate action"))))),"")
A8: ='📥 Stock Data Input'!A8 | B8: ='📥 Stock Data Input'!C8 | C8: ='📥 Stock Data Input'!D8 | D8: ='📥 Stock Data Input'!J8 | E8: ='📥 Stock Data Input'!K8 | F8: ='📥 Stock Data Input'!L8 | G8: ='📥 Stock Data Input'!M8 | H8: ='📥 Stock Data Input'!N8 | I8: ='📥 Stock Data Input'!O8 | J8: =IFERROR(IF('📥 Stock Data Input'!H8="","N/A",IF('📥 Stock Data Input'!N8>'📥 Stock Data Input'!H8/100,"✅ Outperform","❌ Underperform")),"N/A") | K8: =IFERROR(IF('📥 Stock Data Input'!I8="","N/A",IF('📥 Stock Data Input'!N8>'📥 Stock Data Input'!I8/100,"✅ Beat Nifty","❌ Lag Nifty")),"N/A") | L8: =IFERROR(IF('📥 Stock Data Input'!A8="","",IF('📥 Stock Data Input'!K8<5000,"⚠️ Tiny Position",IF('📥 Stock Data Input'!N8<0,"🔴 In Loss",IF(AND('📥 Stock Data Input'!I8<>"",'📥 Stock Data Input'!N8<'📥 Stock Data Input'!I8/100),"🟡 Underperform",IF('📥 Stock Data Input'!N8>0.2,"🟢 Strong","🔵 Hold"))))),"") | M8: =IFERROR(IF('📥 Stock Data Input'!A8="","",IF('📥 Stock Data Input'!K8<5000,"Add qty meaningfully or exit — position too small to matter",IF('📥 Stock Data Input'!N8<-0.2,"Consider exit — loss >20%; re-evaluate thesis",IF(AND('📥 Stock Data Input'!I8<>"",'📥 Stock Data Input'!N8<'📥 Stock Data Input'!I8/100),"Lagging benchmark — review thesis; rotate if 2+ years",IF('📥 Stock Data Input'!N8>0.2,"Strong compounder — hold; consider adding on dips","Hold — monitor quarterly; no immediate action"))))),"")
A9: ='📥 Stock Data Input'!A9 | B9: ='📥 Stock Data Input'!C9 | C9: ='📥 Stock Data Input'!D9 | D9: ='📥 Stock Data Input'!J9 | E9: ='📥 Stock Data Input'!K9 | F9: ='📥 Stock Data Input'!L9 | G9: ='📥 Stock Data Input'!M9 | H9: ='📥 Stock Data Input'!N9 | I9: ='📥 Stock Data Input'!O9 | J9: =IFERROR(IF('📥 Stock Data Input'!H9="","N/A",IF('📥 Stock Data Input'!N9>'📥 Stock Data Input'!H9/100,"✅ Outperform","❌ Underperform")),"N/A") | K9: =IFERROR(IF('📥 Stock Data Input'!I9="","N/A",IF('📥 Stock Data Input'!N9>'📥 Stock Data Input'!I9/100,"✅ Beat Nifty","❌ Lag Nifty")),"N/A") | L9: =IFERROR(IF('📥 Stock Data Input'!A9="","",IF('📥 Stock Data Input'!K9<5000,"⚠️ Tiny Position",IF('📥 Stock Data Input'!N9<0,"🔴 In Loss",IF(AND('📥 Stock Data Input'!I9<>"",'📥 Stock Data Input'!N9<'📥 Stock Data Input'!I9/100),"🟡 Underperform",IF('📥 Stock Data Input'!N9>0.2,"🟢 Strong","🔵 Hold"))))),"") | M9: =IFERROR(IF('📥 Stock Data Input'!A9="","",IF('📥 Stock Data Input'!K9<5000,"Add qty meaningfully or exit — position too small to matter",IF('📥 Stock Data Input'!N9<-0.2,"Consider exit — loss >20%; re-evaluate thesis",IF(AND('📥 Stock Data Input'!I9<>"",'📥 Stock Data Input'!N9<'📥 Stock Data Input'!I9/100),"Lagging benchmark — review thesis; rotate if 2+ years",IF('📥 Stock Data Input'!N9>0.2,"Strong compounder — hold; consider adding on dips","Hold — monitor quarterly; no immediate action"))))),"")
A10: ='📥 Stock Data Input'!A10 | B10: ='📥 Stock Data Input'!C10 | C10: ='📥 Stock Data Input'!D10 | D10: ='📥 Stock Data Input'!J10 | E10: ='📥 Stock Data Input'!K10 | F10: ='📥 Stock Data Input'!L10 | G10: ='📥 Stock Data Input'!M10 | H10: ='📥 Stock Data Input'!N10 | I10: ='📥 Stock Data Input'!O10 | J10: =IFERROR(IF('📥 Stock Data Input'!H10="","N/A",IF('📥 Stock Data Input'!N10>'📥 Stock Data Input'!H10/100,"✅ Outperform","❌ Underperform")),"N/A") | K10: =IFERROR(IF('📥 Stock Data Input'!I10="","N/A",IF('📥 Stock Data Input'!N10>'📥 Stock Data Input'!I10/100,"✅ Beat Nifty","❌ Lag Nifty")),"N/A") | L10: =IFERROR(IF('📥 Stock Data Input'!A10="","",IF('📥 Stock Data Input'!K10<5000,"⚠️ Tiny Position",IF('📥 Stock Data Input'!N10<0,"🔴 In Loss",IF(AND('📥 Stock Data Input'!I10<>"",'📥 Stock Data Input'!N10<'📥 Stock Data Input'!I10/100),"🟡 Underperform",IF('📥 Stock Data Input'!N10>0.2,"🟢 Strong","🔵 Hold"))))),"") | M10: =IFERROR(IF('📥 Stock Data Input'!A10="","",IF('📥 Stock Data Input'!K10<5000,"Add qty meaningfully or exit — position too small to matter",IF('📥 Stock Data Input'!N10<-0.2,"Consider exit — loss >20%; re-evaluate thesis",IF(AND('📥 Stock Data Input'!I10<>"",'📥 Stock Data Input'!N10<'📥 Stock Data Input'!I10/100),"Lagging benchmark — review thesis; rotate if 2+ years",IF('📥 Stock Data Input'!N10>0.2,"Strong compounder — hold; consider adding on dips","Hold — monitor quarterly; no immediate action"))))),"")
A11: ='📥 Stock Data Input'!A11 | B11: ='📥 Stock Data Input'!C11 | C11: ='📥 Stock Data Input'!D11 | D11: ='📥 Stock Data Input'!J11 | E11: ='📥 Stock Data Input'!K11 | F11: ='📥 Stock Data Input'!L11 | G11: ='📥 Stock Data Input'!M11 | H11: ='📥 Stock Data Input'!N11 | I11: ='📥 Stock Data Input'!O11 | J11: =IFERROR(IF('📥 Stock Data Input'!H11="","N/A",IF('📥 Stock Data Input'!N11>'📥 Stock Data Input'!H11/100,"✅ Outperform","❌ Underperform")),"N/A") | K11: =IFERROR(IF('📥 Stock Data Input'!I11="","N/A",IF('📥 Stock Data Input'!N11>'📥 Stock Data Input'!I11/100,"✅ Beat Nifty","❌ Lag Nifty")),"N/A") | L11: =IFERROR(IF('📥 Stock Data Input'!A11="","",IF('📥 Stock Data Input'!K11<5000,"⚠️ Tiny Position",IF('📥 Stock Data Input'!N11<0,"🔴 In Loss",IF(AND('📥 Stock Data Input'!I11<>"",'📥 Stock Data Input'!N11<'📥 Stock Data Input'!I11/100),"🟡 Underperform",IF('📥 Stock Data Input'!N11>0.2,"🟢 Strong","🔵 Hold"))))),"") | M11: =IFERROR(IF('📥 Stock Data Input'!A11="","",IF('📥 Stock Data Input'!K11<5000,"Add qty meaningfully or exit — position too small to matter",IF('📥 Stock Data Input'!N11<-0.2,"Consider exit — loss >20%; re-evaluate thesis",IF(AND('📥 Stock Data Input'!I11<>"",'📥 Stock Data Input'!N11<'📥 Stock Data Input'!I11/100),"Lagging benchmark — review thesis; rotate if 2+ years",IF('📥 Stock Data Input'!N11>0.2,"Strong compounder — hold; consider adding on dips","Hold — monitor quarterly; no immediate action"))))),"")
A12: ='📥 Stock Data Input'!A12 | B12: ='📥 Stock Data Input'!C12 | C12: ='📥 Stock Data Input'!D12 | D12: ='📥 Stock Data Input'!J12 | E12: ='📥 Stock Data Input'!K12 | F12: ='📥 Stock Data Input'!L12 | G12: ='📥 Stock Data Input'!M12 | H12: ='📥 Stock Data Input'!N12 | I12: ='📥 Stock Data Input'!O12 | J12: =IFERROR(IF('📥 Stock Data Input'!H12="","N/A",IF('📥 Stock Data Input'!N12>'📥 Stock Data Input'!H12/100,"✅ Outperform","❌ Underperform")),"N/A") | K12: =IFERROR(IF('📥 Stock Data Input'!I12="","N/A",IF('📥 Stock Data Input'!N12>'📥 Stock Data Input'!I12/100,"✅ Beat Nifty","❌ Lag Nifty")),"N/A") | L12: =IFERROR(IF('📥 Stock Data Input'!A12="","",IF('📥 Stock Data Input'!K12<5000,"⚠️ Tiny Position",IF('📥 Stock Data Input'!N12<0,"🔴 In Loss",IF(AND('📥 Stock Data Input'!I12<>"",'📥 Stock Data Input'!N12<'📥 Stock Data Input'!I12/100),"🟡 Underperform",IF('📥 Stock Data Input'!N12>0.2,"🟢 Strong","🔵 Hold"))))),"") | M12: =IFERROR(IF('📥 Stock Data Input'!A12="","",IF('📥 Stock Data Input'!K12<5000,"Add qty meaningfully or exit — position too small to matter",IF('📥 Stock Data Input'!N12<-0.2,"Consider exit — loss >20%; re-evaluate thesis",IF(AND('📥 Stock Data Input'!I12<>"",'📥 Stock Data Input'!N12<'📥 Stock Data Input'!I12/100),"Lagging benchmark — review thesis; rotate if 2+ years",IF('📥 Stock Data Input'!N12>0.2,"Strong compounder — hold; consider adding on dips","Hold — monitor quarterly; no immediate action"))))),"")
A13: ='📥 Stock Data Input'!A13 | B13: ='📥 Stock Data Input'!C13 | C13: ='📥 Stock Data Input'!D13 | D13: ='📥 Stock Data Input'!J13 | E13: ='📥 Stock Data Input'!K13 | F13: ='📥 Stock Data Input'!L13 | G13: ='📥 Stock Data Input'!M13 | H13: ='📥 Stock Data Input'!N13 | I13: ='📥 Stock Data Input'!O13 | J13: =IFERROR(IF('📥 Stock Data Input'!H13="","N/A",IF('📥 Stock Data Input'!N13>'📥 Stock Data Input'!H13/100,"✅ Outperform","❌ Underperform")),"N/A") | K13: =IFERROR(IF('📥 Stock Data Input'!I13="","N/A",IF('📥 Stock Data Input'!N13>'📥 Stock Data Input'!I13/100,"✅ Beat Nifty","❌ Lag Nifty")),"N/A") | L13: =IFERROR(IF('📥 Stock Data Input'!A13="","",IF('📥 Stock Data Input'!K13<5000,"⚠️ Tiny Position",IF('📥 Stock Data Input'!N13<0,"🔴 In Loss",IF(AND('📥 Stock Data Input'!I13<>"",'📥 Stock Data Input'!N13<'📥 Stock Data Input'!I13/100),"🟡 Underperform",IF('📥 Stock Data Input'!N13>0.2,"🟢 Strong","🔵 Hold"))))),"") | M13: =IFERROR(IF('📥 Stock Data Input'!A13="","",IF('📥 Stock Data Input'!K13<5000,"Add qty meaningfully or exit — position too small to matter",IF('📥 Stock Data Input'!N13<-0.2,"Consider exit — loss >20%; re-evaluate thesis",IF(AND('📥 Stock Data Input'!I13<>"",'📥 Stock Data Input'!N13<'📥 Stock Data Input'!I13/100),"Lagging benchmark — review thesis; rotate if 2+ years",IF('📥 Stock Data Input'!N13>0.2,"Strong compounder — hold; consider adding on dips","Hold — monitor quarterly; no immediate action"))))),"")
A14: ='📥 Stock Data Input'!A14 | B14: ='📥 Stock Data Input'!C14 | C14: ='📥 Stock Data Input'!D14 | D14: ='📥 Stock Data Input'!J14 | E14: ='📥 Stock Data Input'!K14 | F14: ='📥 Stock Data Input'!L14 | G14: ='📥 Stock Data Input'!M14 | H14: ='📥 Stock Data Input'!N14 | I14: ='📥 Stock Data Input'!O14 | J14: =IFERROR(IF('📥 Stock Data Input'!H14="","N/A",IF('📥 Stock Data Input'!N14>'📥 Stock Data Input'!H14/100,"✅ Outperform","❌ Underperform")),"N/A") | K14: =IFERROR(IF('📥 Stock Data Input'!I14="","N/A",IF('📥 Stock Data Input'!N14>'📥 Stock Data Input'!I14/100,"✅ Beat Nifty","❌ Lag Nifty")),"N/A") | L14: =IFERROR(IF('📥 Stock Data Input'!A14="","",IF('📥 Stock Data Input'!K14<5000,"⚠️ Tiny Position",IF('📥 Stock Data Input'!N14<0,"🔴 In Loss",IF(AND('📥 Stock Data Input'!I14<>"",'📥 Stock Data Input'!N14<'📥 Stock Data Input'!I14/100),"🟡 Underperform",IF('📥 Stock Data Input'!N14>0.2,"🟢 Strong","🔵 Hold"))))),"") | M14: =IFERROR(IF('📥 Stock Data Input'!A14="","",IF('📥 Stock Data Input'!K14<5000,"Add qty meaningfully or exit — position too small to matter",IF('📥 Stock Data Input'!N14<-0.2,"Consider exit — loss >20%; re-evaluate thesis",IF(AND('📥 Stock Data Input'!I14<>"",'📥 Stock Data Input'!N14<'📥 Stock Data Input'!I14/100),"Lagging benchmark — review thesis; rotate if 2+ years",IF('📥 Stock Data Input'!N14>0.2,"Strong compounder — hold; consider adding on dips","Hold — monitor quarterly; no immediate action"))))),"")
A15: ='📥 Stock Data Input'!A15 | B15: ='📥 Stock Data Input'!C15 | C15: ='📥 Stock Data Input'!D15 | D15: ='📥 Stock Data Input'!J15 | E15: ='📥 Stock Data Input'!K15 | F15: ='📥 Stock Data Input'!L15 | G15: ='📥 Stock Data Input'!M15 | H15: ='📥 Stock Data Input'!N15 | I15: ='📥 Stock Data Input'!O15 | J15: =IFERROR(IF('📥 Stock Data Input'!H15="","N/A",IF('📥 Stock Data Input'!N15>'📥 Stock Data Input'!H15/100,"✅ Outperform","❌ Underperform")),"N/A") | K15: =IFERROR(IF('📥 Stock Data Input'!I15="","N/A",IF('📥 Stock Data Input'!N15>'📥 Stock Data Input'!I15/100,"✅ Beat Nifty","❌ Lag Nifty")),"N/A") | L15: =IFERROR(IF('📥 Stock Data Input'!A15="","",IF('📥 Stock Data Input'!K15<5000,"⚠️ Tiny Position",IF('📥 Stock Data Input'!N15<0,"🔴 In Loss",IF(AND('📥 Stock Data Input'!I15<>"",'📥 Stock Data Input'!N15<'📥 Stock Data Input'!I15/100),"🟡 Underperform",IF('📥 Stock Data Input'!N15>0.2,"🟢 Strong","🔵 Hold"))))),"") | M15: =IFERROR(IF('📥 Stock Data Input'!A15="","",IF('📥 Stock Data Input'!K15<5000,"Add qty meaningfully or exit — position too small to matter",IF('📥 Stock Data Input'!N15<-0.2,"Consider exit — loss >20%; re-evaluate thesis",IF(AND('📥 Stock Data Input'!I15<>"",'📥 Stock Data Input'!N15<'📥 Stock Data Input'!I15/100),"Lagging benchmark — review thesis; rotate if 2+ years",IF('📥 Stock Data Input'!N15>0.2,"Strong compounder — hold; consider adding on dips","Hold — monitor quarterly; no immediate action"))))),"")
... A53: ='📥 Stock Data Input'!A53 | B53: ='📥 Stock Data Input'!C53 | C53: ='📥 Stock Data Input'!D53 | D53: ='📥 Stock Data Input'!J53 | E53: ='📥 Stock Data Input'!K53 | F53: ='📥 Stock Data Input'!L53 | G53: ='📥 Stock Data Input'!M53 | H53: ='📥 Stock Data Input'!N53 | I53: ='📥 Stock Data Input'!O53 | J53: =IFERROR(IF('📥 Stock Data Input'!H53="","N/A",IF('📥 Stock Data Input'!N53>'📥 Stock Data Input'!H53/100,"✅ Outperform","❌ Underperform")),"N/A") | K53: =IFERROR(IF('📥 Stock Data Input'!I53="","N/A",IF('📥 Stock Data Input'!N53>'📥 Stock Data Input'!I53/100,"✅ Beat Nifty","❌ Lag Nifty")),"N/A") | L53: =IFERROR(IF('📥 Stock Data Input'!A53="","",IF('📥 Stock Data Input'!K53<5000,"⚠️ Tiny Position",IF('📥 Stock Data Input'!N53<0,"🔴 In Loss",IF(AND('📥 Stock Data Input'!I53<>"",'📥 Stock Data Input'!N53<'📥 Stock Data Input'!I53/100),"🟡 Underperform",IF('📥 Stock Data Input'!N53>0.2,"🟢 Strong","🔵 Hold"))))),"") | M53: =IFERROR(IF('📥 Stock Data Input'!A53="","",IF('📥 Stock Data Input'!K53<5000,"Add qty meaningfully or exit — position too small to matter",IF('📥 Stock Data Input'!N53<-0.2,"Consider exit — loss >20%; re-evaluate thesis",IF(AND('📥 Stock Data Input'!I53<>"",'📥 Stock Data Input'!N53<'📥 Stock Data Input'!I53/100),"Lagging benchmark — review thesis; rotate if 2+ years",IF('📥 Stock Data Input'!N53>0.2,"Strong compounder — hold; consider adding on dips","Hold — monitor quarterly; no immediate action"))))),"")

Sheet 📊 MF Analysis
A1: Mutual Fund Portfolio — Automated Analysis
A2: ⚙️ All columns auto-calculated from 📥 MF Data Input. Do NOT edit. Alpha = your CAGR minus benchmark 1Y return.
A3: Fund Name | B3: AMC | C3: Category | D3: Invested (₹) | E3: Current Value (₹) | F3: P&L (₹) | G3: Absolute Return % | H3: CAGR % | I3: Portfolio Wt% | J3: Alpha vs Benchmark | K3: Signal | L3: Recommended Action
A4: ='📥 MF Data Input'!A4 | B4: ='📥 MF Data Input'!B4 | C4: ='📥 MF Data Input'!C4 | D4: ='📥 MF Data Input'!K4 | E4: ='📥 MF Data Input'!L4 | F4: ='📥 MF Data Input'!M4 | G4: ='📥 MF Data Input'!N4 | H4: ='📥 MF Data Input'!O4 | I4: ='📥 MF Data Input'!P4 | J4: =IFERROR(IF('📥 MF Data Input'!I4="","N/A",'📥 MF Data Input'!O4-'📥 MF Data Input'!I4/100),"N/A") | K4: =IFERROR(IF('📥 MF Data Input'!A4="","",IF('📥 MF Data Input'!O4<0,"🔴 Negative Return",IF(AND('📥 MF Data Input'!I4<>"",'📥 MF Data Input'!O4<'📥 MF Data Input'!I4/100),"🟡 Below Benchmark",IF('📥 MF Data Input'!O4>0.15,"🟢 Outperforming","🔵 In Line")))),"") | L4: =IFERROR(IF('📥 MF Data Input'!A4="","",IF('📥 MF Data Input'!O4<0,"Negative returns — review fund; check if macro or fund-specific",IF(AND('📥 MF Data Input'!I4<>"",'📥 MF Data Input'!O4<'📥 MF Data Input'!I4/100),"Lagging benchmark 2+ yrs? Consider switching to index fund",IF('📥 MF Data Input'!O4>0.15,"Strong alpha — hold; consider increasing SIP","Continue SIP; review annually against benchmark")))),"")
A5: ='📥 MF Data Input'!A5 | B5: ='📥 MF Data Input'!B5 | C5: ='📥 MF Data Input'!C5 | D5: ='📥 MF Data Input'!K5 | E5: ='📥 MF Data Input'!L5 | F5: ='📥 MF Data Input'!M5 | G5: ='📥 MF Data Input'!N5 | H5: ='📥 MF Data Input'!O5 | I5: ='📥 MF Data Input'!P5 | J5: =IFERROR(IF('📥 MF Data Input'!I5="","N/A",'📥 MF Data Input'!O5-'📥 MF Data Input'!I5/100),"N/A") | K5: =IFERROR(IF('📥 MF Data Input'!A5="","",IF('📥 MF Data Input'!O5<0,"🔴 Negative Return",IF(AND('📥 MF Data Input'!I5<>"",'📥 MF Data Input'!O5<'📥 MF Data Input'!I5/100),"🟡 Below Benchmark",IF('📥 MF Data Input'!O5>0.15,"🟢 Outperforming","🔵 In Line")))),"") | L5: =IFERROR(IF('📥 MF Data Input'!A5="","",IF('📥 MF Data Input'!O5<0,"Negative returns — review fund; check if macro or fund-specific",IF(AND('📥 MF Data Input'!I5<>"",'📥 MF Data Input'!O5<'📥 MF Data Input'!I5/100),"Lagging benchmark 2+ yrs? Consider switching to index fund",IF('📥 MF Data Input'!O5>0.15,"Strong alpha — hold; consider increasing SIP","Continue SIP; review annually against benchmark")))),"")
A6: ='📥 MF Data Input'!A6 | B6: ='📥 MF Data Input'!B6 | C6: ='📥 MF Data Input'!C6 | D6: ='📥 MF Data Input'!K6 | E6: ='📥 MF Data Input'!L6 | F6: ='📥 MF Data Input'!M6 | G6: ='📥 MF Data Input'!N6 | H6: ='📥 MF Data Input'!O6 | I6: ='📥 MF Data Input'!P6 | J6: =IFERROR(IF('📥 MF Data Input'!I6="","N/A",'📥 MF Data Input'!O6-'📥 MF Data Input'!I6/100),"N/A") | K6: =IFERROR(IF('📥 MF Data Input'!A6="","",IF('📥 MF Data Input'!O6<0,"🔴 Negative Return",IF(AND('📥 MF Data Input'!I6<>"",'📥 MF Data Input'!O6<'📥 MF Data Input'!I6/100),"🟡 Below Benchmark",IF('📥 MF Data Input'!O6>0.15,"🟢 Outperforming","🔵 In Line")))),"") | L6: =IFERROR(IF('📥 MF Data Input'!A6="","",IF('📥 MF Data Input'!O6<0,"Negative returns — review fund; check if macro or fund-specific",IF(AND('📥 MF Data Input'!I6<>"",'📥 MF Data Input'!O6<'📥 MF Data Input'!I6/100),"Lagging benchmark 2+ yrs? Consider switching to index fund",IF('📥 MF Data Input'!O6>0.15,"Strong alpha — hold; consider increasing SIP","Continue SIP; review annually against benchmark")))),"")
A7: ='📥 MF Data Input'!A7 | B7: ='📥 MF Data Input'!B7 | C7: ='📥 MF Data Input'!C7 | D7: ='📥 MF Data Input'!K7 | E7: ='📥 MF Data Input'!L7 | F7: ='📥 MF Data Input'!M7 | G7: ='📥 MF Data Input'!N7 | H7: ='📥 MF Data Input'!O7 | I7: ='📥 MF Data Input'!P7 | J7: =IFERROR(IF('📥 MF Data Input'!I7="","N/A",'📥 MF Data Input'!O7-'📥 MF Data Input'!I7/100),"N/A") | K7: =IFERROR(IF('📥 MF Data Input'!A7="","",IF('📥 MF Data Input'!O7<0,"🔴 Negative Return",IF(AND('📥 MF Data Input'!I7<>"",'📥 MF Data Input'!O7<'📥 MF Data Input'!I7/100),"🟡 Below Benchmark",IF('📥 MF Data Input'!O7>0.15,"🟢 Outperforming","🔵 In Line")))),"") | L7: =IFERROR(IF('📥 MF Data Input'!A7="","",IF('📥 MF Data Input'!O7<0,"Negative returns — review fund; check if macro or fund-specific",IF(AND('📥 MF Data Input'!I7<>"",'📥 MF Data Input'!O7<'📥 MF Data Input'!I7/100),"Lagging benchmark 2+ yrs? Consider switching to index fund",IF('📥 MF Data Input'!O7>0.15,"Strong alpha — hold; consider increasing SIP","Continue SIP; review annually against benchmark")))),"")
A8: ='📥 MF Data Input'!A8 | B8: ='📥 MF Data Input'!B8 | C8: ='📥 MF Data Input'!C8 | D8: ='📥 MF Data Input'!K8 | E8: ='📥 MF Data Input'!L8 | F8: ='📥 MF Data Input'!M8 | G8: ='📥 MF Data Input'!N8 | H8: ='📥 MF Data Input'!O8 | I8: ='📥 MF Data Input'!P8 | J8: =IFERROR(IF('📥 MF Data Input'!I8="","N/A",'📥 MF Data Input'!O8-'📥 MF Data Input'!I8/100),"N/A") | K8: =IFERROR(IF('📥 MF Data Input'!A8="","",IF('📥 MF Data Input'!O8<0,"🔴 Negative Return",IF(AND('📥 MF Data Input'!I8<>"",'📥 MF Data Input'!O8<'📥 MF Data Input'!I8/100),"🟡 Below Benchmark",IF('📥 MF Data Input'!O8>0.15,"🟢 Outperforming","🔵 In Line")))),"") | L8: =IFERROR(IF('📥 MF Data Input'!A8="","",IF('📥 MF Data Input'!O8<0,"Negative returns — review fund; check if macro or fund-specific",IF(AND('📥 MF Data Input'!I8<>"",'📥 MF Data Input'!O8<'📥 MF Data Input'!I8/100),"Lagging benchmark 2+ yrs? Consider switching to index fund",IF('📥 MF Data Input'!O8>0.15,"Strong alpha — hold; consider increasing SIP","Continue SIP; review annually against benchmark")))),"")
A9: ='📥 MF Data Input'!A9 | B9: ='📥 MF Data Input'!B9 | C9: ='📥 MF Data Input'!C9 | D9: ='📥 MF Data Input'!K9 | E9: ='📥 MF Data Input'!L9 | F9: ='📥 MF Data Input'!M9 | G9: ='📥 MF Data Input'!N9 | H9: ='📥 MF Data Input'!O9 | I9: ='📥 MF Data Input'!P9 | J9: =IFERROR(IF('📥 MF Data Input'!I9="","N/A",'📥 MF Data Input'!O9-'📥 MF Data Input'!I9/100),"N/A") | K9: =IFERROR(IF('📥 MF Data Input'!A9="","",IF('📥 MF Data Input'!O9<0,"🔴 Negative Return",IF(AND('📥 MF Data Input'!I9<>"",'📥 MF Data Input'!O9<'📥 MF Data Input'!I9/100),"🟡 Below Benchmark",IF('📥 MF Data Input'!O9>0.15,"🟢 Outperforming","🔵 In Line")))),"") | L9: =IFERROR(IF('📥 MF Data Input'!A9="","",IF('📥 MF Data Input'!O9<0,"Negative returns — review fund; check if macro or fund-specific",IF(AND('📥 MF Data Input'!I9<>"",'📥 MF Data Input'!O9<'📥 MF Data Input'!I9/100),"Lagging benchmark 2+ yrs? Consider switching to index fund",IF('📥 MF Data Input'!O9>0.15,"Strong alpha — hold; consider increasing SIP","Continue SIP; review annually against benchmark")))),"")
A10: ='📥 MF Data Input'!A10 | B10: ='📥 MF Data Input'!B10 | C10: ='📥 MF Data Input'!C10 | D10: ='📥 MF Data Input'!K10 | E10: ='📥 MF Data Input'!L10 | F10: ='📥 MF Data Input'!M10 | G10: ='📥 MF Data Input'!N10 | H10: ='📥 MF Data Input'!O10 | I10: ='📥 MF Data Input'!P10 | J10: =IFERROR(IF('📥 MF Data Input'!I10="","N/A",'📥 MF Data Input'!O10-'📥 MF Data Input'!I10/100),"N/A") | K10: =IFERROR(IF('📥 MF Data Input'!A10="","",IF('📥 MF Data Input'!O10<0,"🔴 Negative Return",IF(AND('📥 MF Data Input'!I10<>"",'📥 MF Data Input'!O10<'📥 MF Data Input'!I10/100),"🟡 Below Benchmark",IF('📥 MF Data Input'!O10>0.15,"🟢 Outperforming","🔵 In Line")))),"") | L10: =IFERROR(IF('📥 MF Data Input'!A10="","",IF('📥 MF Data Input'!O10<0,"Negative returns — review fund; check if macro or fund-specific",IF(AND('📥 MF Data Input'!I10<>"",'📥 MF Data Input'!O10<'📥 MF Data Input'!I10/100),"Lagging benchmark 2+ yrs? Consider switching to index fund",IF('📥 MF Data Input'!O10>0.15,"Strong alpha — hold; consider increasing SIP","Continue SIP; review annually against benchmark")))),"")
A11: ='📥 MF Data Input'!A11 | B11: ='📥 MF Data Input'!B11 | C11: ='📥 MF Data Input'!C11 | D11: ='📥 MF Data Input'!K11 | E11: ='📥 MF Data Input'!L11 | F11: ='📥 MF Data Input'!M11 | G11: ='📥 MF Data Input'!N11 | H11: ='📥 MF Data Input'!O11 | I11: ='📥 MF Data Input'!P11 | J11: =IFERROR(IF('📥 MF Data Input'!I11="","N/A",'📥 MF Data Input'!O11-'📥 MF Data Input'!I11/100),"N/A") | K11: =IFERROR(IF('📥 MF Data Input'!A11="","",IF('📥 MF Data Input'!O11<0,"🔴 Negative Return",IF(AND('📥 MF Data Input'!I11<>"",'📥 MF Data Input'!O11<'📥 MF Data Input'!I11/100),"🟡 Below Benchmark",IF('📥 MF Data Input'!O11>0.15,"🟢 Outperforming","🔵 In Line")))),"") | L11: =IFERROR(IF('📥 MF Data Input'!A11="","",IF('📥 MF Data Input'!O11<0,"Negative returns — review fund; check if macro or fund-specific",IF(AND('📥 MF Data Input'!I11<>"",'📥 MF Data Input'!O11<'📥 MF Data Input'!I11/100),"Lagging benchmark 2+ yrs? Consider switching to index fund",IF('📥 MF Data Input'!O11>0.15,"Strong alpha — hold; consider increasing SIP","Continue SIP; review annually against benchmark")))),"")
A12: ='📥 MF Data Input'!A12 | B12: ='📥 MF Data Input'!B12 | C12: ='📥 MF Data Input'!C12 | D12: ='📥 MF Data Input'!K12 | E12: ='📥 MF Data Input'!L12 | F12: ='📥 MF Data Input'!M12 | G12: ='📥 MF Data Input'!N12 | H12: ='📥 MF Data Input'!O12 | I12: ='📥 MF Data Input'!P12 | J12: =IFERROR(IF('📥 MF Data Input'!I12="","N/A",'📥 MF Data Input'!O12-'📥 MF Data Input'!I12/100),"N/A") | K12: =IFERROR(IF('📥 MF Data Input'!A12="","",IF('📥 MF Data Input'!O12<0,"🔴 Negative Return",IF(AND('📥 MF Data Input'!I12<>"",'📥 MF Data Input'!O12<'📥 MF Data Input'!I12/100),"🟡 Below Benchmark",IF('📥 MF Data Input'!O12>0.15,"🟢 Outperforming","🔵 In Line")))),"") | L12: =IFERROR(IF('📥 MF Data Input'!A12="","",IF('📥 MF Data Input'!O12<0,"Negative returns — review fund; check if macro or fund-specific",IF(AND('📥 MF Data Input'!I12<>"",'📥 MF Data Input'!O12<'📥 MF Data Input'!I12/100),"Lagging benchmark 2+ yrs? Consider switching to index fund",IF('📥 MF Data Input'!O12>0.15,"Strong alpha — hold; consider increasing SIP","Continue SIP; review annually against benchmark")))),"")
A13: ='📥 MF Data Input'!A13 | B13: ='📥 MF Data Input'!B13 | C13: ='📥 MF Data Input'!C13 | D13: ='📥 MF Data Input'!K13 | E13: ='📥 MF Data Input'!L13 | F13: ='📥 MF Data Input'!M13 | G13: ='📥 MF Data Input'!N13 | H13: ='📥 MF Data Input'!O13 | I13: ='📥 MF Data Input'!P13 | J13: =IFERROR(IF('📥 MF Data Input'!I13="","N/A",'📥 MF Data Input'!O13-'📥 MF Data Input'!I13/100),"N/A") | K13: =IFERROR(IF('📥 MF Data Input'!A13="","",IF('📥 MF Data Input'!O13<0,"🔴 Negative Return",IF(AND('📥 MF Data Input'!I13<>"",'📥 MF Data Input'!O13<'📥 MF Data Input'!I13/100),"🟡 Below Benchmark",IF('📥 MF Data Input'!O13>0.15,"🟢 Outperforming","🔵 In Line")))),"") | L13: =IFERROR(IF('📥 MF Data Input'!A13="","",IF('📥 MF Data Input'!O13<0,"Negative returns — review fund; check if macro or fund-specific",IF(AND('📥 MF Data Input'!I13<>"",'📥 MF Data Input'!O13<'📥 MF Data Input'!I13/100),"Lagging benchmark 2+ yrs? Consider switching to index fund",IF('📥 MF Data Input'!O13>0.15,"Strong alpha — hold; consider increasing SIP","Continue SIP; review annually against benchmark")))),"")
A14: ='📥 MF Data Input'!A14 | B14: ='📥 MF Data Input'!B14 | C14: ='📥 MF Data Input'!C14 | D14: ='📥 MF Data Input'!K14 | E14: ='📥 MF Data Input'!L14 | F14: ='📥 MF Data Input'!M14 | G14: ='📥 MF Data Input'!N14 | H14: ='📥 MF Data Input'!O14 | I14: ='📥 MF Data Input'!P14 | J14: =IFERROR(IF('📥 MF Data Input'!I14="","N/A",'📥 MF Data Input'!O14-'📥 MF Data Input'!I14/100),"N/A") | K14: =IFERROR(IF('📥 MF Data Input'!A14="","",IF('📥 MF Data Input'!O14<0,"🔴 Negative Return",IF(AND('📥 MF Data Input'!I14<>"",'📥 MF Data Input'!O14<'📥 MF Data Input'!I14/100),"🟡 Below Benchmark",IF('📥 MF Data Input'!O14>0.15,"🟢 Outperforming","🔵 In Line")))),"") | L14: =IFERROR(IF('📥 MF Data Input'!A14="","",IF('📥 MF Data Input'!O14<0,"Negative returns — review fund; check if macro or fund-specific",IF(AND('📥 MF Data Input'!I14<>"",'📥 MF Data Input'!O14<'📥 MF Data Input'!I14/100),"Lagging benchmark 2+ yrs? Consider switching to index fund",IF('📥 MF Data Input'!O14>0.15,"Strong alpha — hold; consider increasing SIP","Continue SIP; review annually against benchmark")))),"")
A15: ='📥 MF Data Input'!A15 | B15: ='📥 MF Data Input'!B15 | C15: ='📥 MF Data Input'!C15 | D15: ='📥 MF Data Input'!K15 | E15: ='📥 MF Data Input'!L15 | F15: ='📥 MF Data Input'!M15 | G15: ='📥 MF Data Input'!N15 | H15: ='📥 MF Data Input'!O15 | I15: ='📥 MF Data Input'!P15 | J15: =IFERROR(IF('📥 MF Data Input'!I15="","N/A",'📥 MF Data Input'!O15-'📥 MF Data Input'!I15/100),"N/A") | K15: =IFERROR(IF('📥 MF Data Input'!A15="","",IF('📥 MF Data Input'!O15<0,"🔴 Negative Return",IF(AND('📥 MF Data Input'!I15<>"",'📥 MF Data Input'!O15<'📥 MF Data Input'!I15/100),"🟡 Below Benchmark",IF('📥 MF Data Input'!O15>0.15,"🟢 Outperforming","🔵 In Line")))),"") | L15: =IFERROR(IF('📥 MF Data Input'!A15="","",IF('📥 MF Data Input'!O15<0,"Negative returns — review fund; check if macro or fund-specific",IF(AND('📥 MF Data Input'!I15<>"",'📥 MF Data Input'!O15<'📥 MF Data Input'!I15/100),"Lagging benchmark 2+ yrs? Consider switching to index fund",IF('📥 MF Data Input'!O15>0.15,"Strong alpha — hold; consider increasing SIP","Continue SIP; review annually against benchmark")))),"")
... A43: ='📥 MF Data Input'!A43 | B43: ='📥 MF Data Input'!B43 | C43: ='📥 MF Data Input'!C43 | D43: ='📥 MF Data Input'!K43 | E43: ='📥 MF Data Input'!L43 | F43: ='📥 MF Data Input'!M43 | G43: ='📥 MF Data Input'!N43 | H43: ='📥 MF Data Input'!O43 | I43: ='📥 MF Data Input'!P43 | J43: =IFERROR(IF('📥 MF Data Input'!I43="","N/A",'📥 MF Data Input'!O43-'📥 MF Data Input'!I43/100),"N/A") | K43: =IFERROR(IF('📥 MF Data Input'!A43="","",IF('📥 MF Data Input'!O43<0,"🔴 Negative Return",IF(AND('📥 MF Data Input'!I43<>"",'📥 MF Data Input'!O43<'📥 MF Data Input'!I43/100),"🟡 Below Benchmark",IF('📥 MF Data Input'!O43>0.15,"🟢 Outperforming","🔵 In Line")))),"") | L43: =IFERROR(IF('📥 MF Data Input'!A43="","",IF('📥 MF Data Input'!O43<0,"Negative returns — review fund; check if macro or fund-specific",IF(AND('📥 MF Data Input'!I43<>"",'📥 MF Data Input'!O43<'📥 MF Data Input'!I43/100),"Lagging benchmark 2+ yrs? Consider switching to index fund",IF('📥 MF Data Input'!O43>0.15,"Strong alpha — hold; consider increasing SIP","Continue SIP; review annually against benchmark")))),"")

Sheet 📈 Sector Allocation
A1: Sector-Wise Equity Allocation
A2: ⚙️ Auto-calculated from Stock Data Input. Ensure you fill the Sector column (Column C) in the stock input sheet correctly for this to work.
A3: Sector | B3: No. of Stocks | C3: Total Invested (₹) | D3: Current Value (₹) | E3: P&L (₹) | F3: Wt % of Portfolio | G3: Concentration Flag
A4: Banking & Finance | B4: =COUNTIF('📥 Stock Data Input'!$C$4:$C$53,A4) | C4: =SUMIF('📥 Stock Data Input'!$C$4:$C$53,A4,'📥 Stock Data Input'!$J$4:$J$53) | D4: =SUMIF('📥 Stock Data Input'!$C$4:$C$53,A4,'📥 Stock Data Input'!$K$4:$K$53) | E4: =IFERROR(D4-C4,0) | F4: =IFERROR(D4/'📥 Stock Data Input'!$K$54,0) | G4: =IF(F4>0.3,"⚠️ High Concentration",IF(F4>0.2,"🟡 Moderate","✅ Diversified"))
A5: IT & Technology | B5: =COUNTIF('📥 Stock Data Input'!$C$4:$C$53,A5) | C5: =SUMIF('📥 Stock Data Input'!$C$4:$C$53,A5,'📥 Stock Data Input'!$J$4:$J$53) | D5: =SUMIF('📥 Stock Data Input'!$C$4:$C$53,A5,'📥 Stock Data Input'!$K$4:$K$53) | E5: =IFERROR(D5-C5,0) | F5: =IFERROR(D5/'📥 Stock Data Input'!$K$54,0) | G5: =IF(F5>0.3,"⚠️ High Concentration",IF(F5>0.2,"🟡 Moderate","✅ Diversified"))
A6: FMCG & Consumer | B6: =COUNTIF('📥 Stock Data Input'!$C$4:$C$53,A6) | C6: =SUMIF('📥 Stock Data Input'!$C$4:$C$53,A6,'📥 Stock Data Input'!$J$4:$J$53) | D6: =SUMIF('📥 Stock Data Input'!$C$4:$C$53,A6,'📥 Stock Data Input'!$K$4:$K$53) | E6: =IFERROR(D6-C6,0) | F6: =IFERROR(D6/'📥 Stock Data Input'!$K$54,0) | G6: =IF(F6>0.3,"⚠️ High Concentration",IF(F6>0.2,"🟡 Moderate","✅ Diversified"))
A7: Pharma & Healthcare | B7: =COUNTIF('📥 Stock Data Input'!$C$4:$C$53,A7) | C7: =SUMIF('📥 Stock Data Input'!$C$4:$C$53,A7,'📥 Stock Data Input'!$J$4:$J$53) | D7: =SUMIF('📥 Stock Data Input'!$C$4:$C$53,A7,'📥 Stock Data Input'!$K$4:$K$53) | E7: =IFERROR(D7-C7,0) | F7: =IFERROR(D7/'📥 Stock Data Input'!$K$54,0) | G7: =IF(F7>0.3,"⚠️ High Concentration",IF(F7>0.2,"🟡 Moderate","✅ Diversified"))
A8: Auto & Auto Ancillaries | B8: =COUNTIF('📥 Stock Data Input'!$C$4:$C$53,A8) | C8: =SUMIF('📥 Stock Data Input'!$C$4:$C$53,A8,'📥 Stock Data Input'!$J$4:$J$53) | D8: =SUMIF('📥 Stock Data Input'!$C$4:$C$53,A8,'📥 Stock Data Input'!$K$4:$K$53) | E8: =IFERROR(D8-C8,0) | F8: =IFERROR(D8/'📥 Stock Data Input'!$K$54,0) | G8: =IF(F8>0.3,"⚠️ High Concentration",IF(F8>0.2,"🟡 Moderate","✅ Diversified"))
A9: Metals & Mining | B9: =COUNTIF('📥 Stock Data Input'!$C$4:$C$53,A9) | C9: =SUMIF('📥 Stock Data Input'!$C$4:$C$53,A9,'📥 Stock Data Input'!$J$4:$J$53) | D9: =SUMIF('📥 Stock Data Input'!$C$4:$C$53,A9,'📥 Stock Data Input'!$K$4:$K$53) | E9: =IFERROR(D9-C9,0) | F9: =IFERROR(D9/'📥 Stock Data Input'!$K$54,0) | G9: =IF(F9>0.3,"⚠️ High Concentration",IF(F9>0.2,"🟡 Moderate","✅ Diversified"))
A10: Energy & Oil & Gas | B10: =COUNTIF('📥 Stock Data Input'!$C$4:$C$53,A10) | C10: =SUMIF('📥 Stock Data Input'!$C$4:$C$53,A10,'📥 Stock Data Input'!$J$4:$J$53) | D10: =SUMIF('📥 Stock Data Input'!$C$4:$C$53,A10,'📥 Stock Data Input'!$K$4:$K$53) | E10: =IFERROR(D10-C10,0) | F10: =IFERROR(D10/'📥 Stock Data Input'!$K$54,0) | G10: =IF(F10>0.3,"⚠️ High Concentration",IF(F10>0.2,"🟡 Moderate","✅ Diversified"))
A11: Cement & Infra | B11: =COUNTIF('📥 Stock Data Input'!$C$4:$C$53,A11) | C11: =SUMIF('📥 Stock Data Input'!$C$4:$C$53,A11,'📥 Stock Data Input'!$J$4:$J$53) | D11: =SUMIF('📥 Stock Data Input'!$C$4:$C$53,A11,'📥 Stock Data Input'!$K$4:$K$53) | E11: =IFERROR(D11-C11,0) | F11: =IFERROR(D11/'📥 Stock Data Input'!$K$54,0) | G11: =IF(F11>0.3,"⚠️ High Concentration",IF(F11>0.2,"🟡 Moderate","✅ Diversified"))
A12: Chemicals | B12: =COUNTIF('📥 Stock Data Input'!$C$4:$C$53,A12) | C12: =SUMIF('📥 Stock Data Input'!$C$4:$C$53,A12,'📥 Stock Data Input'!$J$4:$J$53) | D12: =SUMIF('📥 Stock Data Input'!$C$4:$C$53,A12,'📥 Stock Data Input'!$K$4:$K$53) | E12: =IFERROR(D12-C12,0) | F12: =IFERROR(D12/'📥 Stock Data Input'!$K$54,0) | G12: =IF(F12>0.3,"⚠️ High Concentration",IF(F12>0.2,"🟡 Moderate","✅ Diversified"))
A13: Telecom | B13: =COUNTIF('📥 Stock Data Input'!$C$4:$C$53,A13) | C13: =SUMIF('📥 Stock Data Input'!$C$4:$C$53,A13,'📥 Stock Data Input'!$J$4:$J$53) | D13: =SUMIF('📥 Stock Data Input'!$C$4:$C$53,A13,'📥 Stock Data Input'!$K$4:$K$53) | E13: =IFERROR(D13-C13,0) | F13: =IFERROR(D13/'📥 Stock Data Input'!$K$54,0) | G13: =IF(F13>0.3,"⚠️ High Concentration",IF(F13>0.2,"🟡 Moderate","✅ Diversified"))
A14: Real Estate | B14: =COUNTIF('📥 Stock Data Input'!$C$4:$C$53,A14) | C14: =SUMIF('📥 Stock Data Input'!$C$4:$C$53,A14,'📥 Stock Data Input'!$J$4:$J$53) | D14: =SUMIF('📥 Stock Data Input'!$C$4:$C$53,A14,'📥 Stock Data Input'!$K$4:$K$53) | E14: =IFERROR(D14-C14,0) | F14: =IFERROR(D14/'📥 Stock Data Input'!$K$54,0) | G14: =IF(F14>0.3,"⚠️ High Concentration",IF(F14>0.2,"🟡 Moderate","✅ Diversified"))
A15: Textiles | B15: =COUNTIF('📥 Stock Data Input'!$C$4:$C$53,A15) | C15: =SUMIF('📥 Stock Data Input'!$C$4:$C$53,A15,'📥 Stock Data Input'!$J$4:$J$53) | D15: =SUMIF('📥 Stock Data Input'!$C$4:$C$53,A15,'📥 Stock Data Input'!$K$4:$K$53) | E15: =IFERROR(D15-C15,0) | F15: =IFERROR(D15/'📥 Stock Data Input'!$K$54,0) | G15: =IF(F15>0.3,"⚠️ High Concentration",IF(F15>0.2,"🟡 Moderate","✅ Diversified"))
A16: Others | B16: =COUNTIF('📥 Stock Data Input'!$C$4:$C$53,A16) | C16: =SUMIF('📥 Stock Data Input'!$C$4:$C$53,A16,'📥 Stock Data Input'!$J$4:$J$53) | D16: =SUMIF('📥 Stock Data Input'!$C$4:$C$53,A16,'📥 Stock Data Input'!$K$4:$K$53) | E16: =IFERROR(D16-C16,0) | F16: =IFERROR(D16/'📥 Stock Data Input'!$K$54,0) | G16: =IF(F16>0.3,"⚠️ High Concentration",IF(F16>0.2,"🟡 Moderate","✅ Diversified"))
A17: TOTAL | B17: =SUM(B4:B16) | C17: =SUM(C4:C16) | D17: =SUM(D4:D16) | E17: =SUM(E4:E16)
A19: ⚠️ Concentration Risk Note: Any single sector above 30% of portfolio warrants diversification review. Ideal: no sector >25%.

Sheet ⚠️ Risk & Signals
A1: Risk Flags & Action Signals — Stocks & Mutual Funds
A2: ⚙️ Auto-generated. All signals pull from analysis sheets. Update prices in input sheets to refresh.
A4: 📊 PORTFOLIO SIGNALS SUMMARY
A5: Metric | B5: Count
A6: Total stocks in portfolio | H6: =COUNTA('📥 Stock Data Input'!A4:A53)
A7: 🟢 Strong performers (return >20%) | H7: =COUNTIF('📊 Stock Analysis'!G4:G53,">0.2")
A8: 🔴 Positions in loss (return <0) | H8: =COUNTIF('📊 Stock Analysis'!G4:G53,"<0")
A9: 🟡 Underperforming vs Nifty | H9: =COUNTIF('📊 Stock Analysis'!K4:K53,"❌ Lag Nifty")
A10: ⚠️ Tiny positions (current value <₹10,000) | H10: =COUNTIF('📊 Stock Analysis'!E4:E53,"<10000")
A11: Total MFs in portfolio | H11: =COUNTA('📥 MF Data Input'!A4:A43)
A12: 🟢 MFs outperforming benchmark | H12: =COUNTIF('📊 MF Analysis'!K4:K43,"🟢 Outperforming")
A13: 🟡 MFs below benchmark | H13: =COUNTIF('📊 MF Analysis'!K4:K43,"🟡 Below Benchmark")
A14: 🔴 MFs with negative returns | H14: =COUNTIF('📊 MF Analysis'!K4:K43,"🔴 Negative Return")
A16: DETAILED ACTION FLAGS — STOCKS
A17: Scrip Name | B17: Current Value (₹) | C17: Return % | D17: Ann. XIRR % | E17: vs Nifty | F17: Signal | G17: Priority | H17: Recommended Action
A18: ='📥 Stock Data Input'!A5 | B18: ='📥 Stock Data Input'!K5 | C18: ='📥 Stock Data Input'!M5 | D18: ='📥 Stock Data Input'!N5 | E18: ='📊 Stock Analysis'!K5 | F18: ='📊 Stock Analysis'!L5 | G18: =IFERROR(IF('📥 Stock Data Input'!A5="","",IF('📥 Stock Data Input'!M5<-0.3,"🔴 HIGH",IF(OR('📥 Stock Data Input'!M5<0,'📥 Stock Data Input'!K5<5000),"🟡 MEDIUM","🔵 LOW"))),"") | H18: ='📊 Stock Analysis'!M5
A19: ='📥 Stock Data Input'!A6 | B19: ='📥 Stock Data Input'!K6 | C19: ='📥 Stock Data Input'!M6 | D19: ='📥 Stock Data Input'!N6 | E19: ='📊 Stock Analysis'!K6 | F19: ='📊 Stock Analysis'!L6 | G19: =IFERROR(IF('📥 Stock Data Input'!A6="","",IF('📥 Stock Data Input'!M6<-0.3,"🔴 HIGH",IF(OR('📥 Stock Data Input'!M6<0,'📥 Stock Data Input'!K6<5000),"🟡 MEDIUM","🔵 LOW"))),"") | H19: ='📊 Stock Analysis'!M6
A20: ='📥 Stock Data Input'!A7 | B20: ='📥 Stock Data Input'!K7 | C20: ='📥 Stock Data Input'!M7 | D20: ='📥 Stock Data Input'!N7 | E20: ='📊 Stock Analysis'!K7 | F20: ='📊 Stock Analysis'!L7 | G20: =IFERROR(IF('📥 Stock Data Input'!A7="","",IF('📥 Stock Data Input'!M7<-0.3,"🔴 HIGH",IF(OR('📥 Stock Data Input'!M7<0,'📥 Stock Data Input'!K7<5000),"🟡 MEDIUM","🔵 LOW"))),"") | H20: ='📊 Stock Analysis'!M7
A21: ='📥 Stock Data Input'!A8 | B21: ='📥 Stock Data Input'!K8 | C21: ='📥 Stock Data Input'!M8 | D21: ='📥 Stock Data Input'!N8 | E21: ='📊 Stock Analysis'!K8 | F21: ='📊 Stock Analysis'!L8 | G21: =IFERROR(IF('📥 Stock Data Input'!A8="","",IF('📥 Stock Data Input'!M8<-0.3,"🔴 HIGH",IF(OR('📥 Stock Data Input'!M8<0,'📥 Stock Data Input'!K8<5000),"🟡 MEDIUM","🔵 LOW"))),"") | H21: ='📊 Stock Analysis'!M8
A22: ='📥 Stock Data Input'!A9 | B22: ='📥 Stock Data Input'!K9 | C22: ='📥 Stock Data Input'!M9 | D22: ='📥 Stock Data Input'!N9 | E22: ='📊 Stock Analysis'!K9 | F22: ='📊 Stock Analysis'!L9 | G22: =IFERROR(IF('📥 Stock Data Input'!A9="","",IF('📥 Stock Data Input'!M9<-0.3,"🔴 HIGH",IF(OR('📥 Stock Data Input'!M9<0,'📥 Stock Data Input'!K9<5000),"🟡 MEDIUM","🔵 LOW"))),"") | H22: ='📊 Stock Analysis'!M9
A23: ='📥 Stock Data Input'!A10 | B23: ='📥 Stock Data Input'!K10 | C23: ='📥 Stock Data Input'!M10 | D23: ='📥 Stock Data Input'!N10 | E23: ='📊 Stock Analysis'!K10 | F23: ='📊 Stock Analysis'!L10 | G23: =IFERROR(IF('📥 Stock Data Input'!A10="","",IF('📥 Stock Data Input'!M10<-0.3,"🔴 HIGH",IF(OR('📥 Stock Data Input'!M10<0,'📥 Stock Data Input'!K10<5000),"🟡 MEDIUM","🔵 LOW"))),"") | H23: ='📊 Stock Analysis'!M10
